Workbook

Sheet 📋 Задачи
A1: 📋 ТРЕКЕР ЗАДАЧ — ИТ ПОДДЕРЖКА
A2: ID | B2: Отправитель | C2: Тема письма | D2: Содержание письма | E2: Описание задачи (своими словами) | F2: Дата поступления | G2: Дата и время задачи | H2: Срок выполнения (план) | I2: Дата и время выполнения (факт) | J2: Статус | K2: Приоритет | L2: Исполнитель | M2: Квартал (план) | N2: Квартал (факт) | O2: Решение / ответ | P2: Комментарии | Q2: Управление / Отдел | R2: Тип задачи
A3: 1 | B3: Иванов А.С. (Отдел кадров) | C3: Анализ звонка клиента | D3: Добрый день, прошу проверить holdtime при звонке клиента 27.04.2025 в 09:42, номер +7 701 XXX-XX-XX | E3: Проверить holdtime по звонку — дата, время и номер клиента указаны | F3: 45774 | G3: 45774.427 | H3: 45774.458 | I3: 45774.443 | J3: Выполнена | K3: Высокий | L3: Нуржан | M3: =IF(OR(G3="",NOT(ISNUMBER(G3))),"","Q"&INT((MONTH(G3)-1)/3+1)&" "&YEAR(G3)) -> Q2 2025 | N3: =IF(OR(I3="",NOT(ISNUMBER(I3))),"","Q"&INT((MONTH(I3)-1)/3+1)&" "&YEAR(I3)) -> Q2 2025 | O3: Holdtime составил 1 мин 42 сек. Ответ направлен письмом. | Q3: Отдел кадров | R3: Анализ звонка
A4: =IF(B4="","",ROW()-2) | M4: =IF(OR(G4="",NOT(ISNUMBER(G4))),"","Q"&INT((MONTH(G4)-1)/3+1)&" "&YEAR(G4)) | N4: =IF(OR(I4="",NOT(ISNUMBER(I4))),"","Q"&INT((MONTH(I4)-1)/3+1)&" "&YEAR(I4))
A5: =IF(B5="","",ROW()-2) | M5: =IF(OR(G5="",NOT(ISNUMBER(G5))),"","Q"&INT((MONTH(G5)-1)/3+1)&" "&YEAR(G5)) | N5: =IF(OR(I5="",NOT(ISNUMBER(I5))),"","Q"&INT((MONTH(I5)-1)/3+1)&" "&YEAR(I5))
A6: =IF(B6="","",ROW()-2) | M6: =IF(OR(G6="",NOT(ISNUMBER(G6))),"","Q"&INT((MONTH(G6)-1)/3+1)&" "&YEAR(G6)) | N6: =IF(OR(I6="",NOT(ISNUMBER(I6))),"","Q"&INT((MONTH(I6)-1)/3+1)&" "&YEAR(I6))
A7: =IF(B7="","",ROW()-2) | M7: =IF(OR(G7="",NOT(ISNUMBER(G7))),"","Q"&INT((MONTH(G7)-1)/3+1)&" "&YEAR(G7)) | N7: =IF(OR(I7="",NOT(ISNUMBER(I7))),"","Q"&INT((MONTH(I7)-1)/3+1)&" "&YEAR(I7))
A8: =IF(B8="","",ROW()-2) | M8: =IF(OR(G8="",NOT(ISNUMBER(G8))),"","Q"&INT((MONTH(G8)-1)/3+1)&" "&YEAR(G8)) | N8: =IF(OR(I8="",NOT(ISNUMBER(I8))),"","Q"&INT((MONTH(I8)-1)/3+1)&" "&YEAR(I8))
A9: =IF(B9="","",ROW()-2) | M9: =IF(OR(G9="",NOT(ISNUMBER(G9))),"","Q"&INT((MONTH(G9)-1)/3+1)&" "&YEAR(G9)) | N9: =IF(OR(I9="",NOT(ISNUMBER(I9))),"","Q"&INT((MONTH(I9)-1)/3+1)&" "&YEAR(I9))
A10: =IF(B10="","",ROW()-2) | M10: =IF(OR(G10="",NOT(ISNUMBER(G10))),"","Q"&INT((MONTH(G10)-1)/3+1)&" "&YEAR(G10)) | N10: =IF(OR(I10="",NOT(ISNUMBER(I10))),"","Q"&INT((MONTH(I10)-1)/3+1)&" "&YEAR(I10))
A11: =IF(B11="","",ROW()-2) | M11: =IF(OR(G11="",NOT(ISNUMBER(G11))),"","Q"&INT((MONTH(G11)-1)/3+1)&" "&YEAR(G11)) | N11: =IF(OR(I11="",NOT(ISNUMBER(I11))),"","Q"&INT((MONTH(I11)-1)/3+1)&" "&YEAR(I11))
A12: =IF(B12="","",ROW()-2) | M12: =IF(OR(G12="",NOT(ISNUMBER(G12))),"","Q"&INT((MONTH(G12)-1)/3+1)&" "&YEAR(G12)) | N12: =IF(OR(I12="",NOT(ISNUMBER(I12))),"","Q"&INT((MONTH(I12)-1)/3+1)&" "&YEAR(I12))
A13: =IF(B13="","",ROW()-2) | M13: =IF(OR(G13="",NOT(ISNUMBER(G13))),"","Q"&INT((MONTH(G13)-1)/3+1)&" "&YEAR(G13)) | N13: =IF(OR(I13="",NOT(ISNUMBER(I13))),"","Q"&INT((MONTH(I13)-1)/3+1)&" "&YEAR(I13))
A14: =IF(B14="","",ROW()-2) | M14: =IF(OR(G14="",NOT(ISNUMBER(G14))),"","Q"&INT((MONTH(G14)-1)/3+1)&" "&YEAR(G14)) | N14: =IF(OR(I14="",NOT(ISNUMBER(I14))),"","Q"&INT((MONTH(I14)-1)/3+1)&" "&YEAR(I14))
A15: =IF(B15="","",ROW()-2) | M15: =IF(OR(G15="",NOT(ISNUMBER(G15))),"","Q"&INT((MONTH(G15)-1)/3+1)&" "&YEAR(G15)) | N15: =IF(OR(I15="",NOT(ISNUMBER(I15))),"","Q"&INT((MONTH(I15)-1)/3+1)&" "&YEAR(I15))
... A53: =IF(B53="","",ROW()-2) | M53: =IF(OR(G53="",NOT(ISNUMBER(G53))),"","Q"&INT((MONTH(G53)-1)/3+1)&" "&YEAR(G53)) | N53: =IF(OR(I53="",NOT(ISNUMBER(I53))),"","Q"&INT((MONTH(I53)-1)/3+1)&" "&YEAR(I53))

Sheet 📊 Сводный отчёт
A1: 📊 СВОДНЫЙ КВАРТАЛЬНЫЙ ОТЧЁТ
A2: ⚡ Данные обновляются автоматически из листа «📋 Задачи». Выберите квартал в ячейке B4.
A4: 🔎 Выбранный квартал (например: Q2 2025): | B4: Q2 2025
A6: 📌 1. Общая статистика за квартал
A7: Всего задач поступило | B7: =COUNTIF('📋 Задачи'!M3:M200,$B$4) -> 1
A8: Всего задач выполнено | B8: =COUNTIFS('📋 Задачи'!J3:J200,"Выполнена",'📋 Задачи'!N3:N200,$B$4) -> 1
A9: % выполнения | B9: =IFERROR(B8/B7,0) -> 1
A10: Задач в работе | B10: =COUNTIFS('📋 Задачи'!J3:J200,"В работе",'📋 Задачи'!M3:M200,$B$4) -> 0
A11: Задач в ожидании | B11: =COUNTIFS('📋 Задачи'!J3:J200,"В ожидании",'📋 Задачи'!M3:M200,$B$4) -> 0
A12: Задач в бэклоге | B12: =COUNTIFS('📋 Задачи'!J3:J200,"В бэклоге",'📋 Задачи'!M3:M200,$B$4) -> 0
A13: Задач отменено | B13: =COUNTIFS('📋 Задачи'!J3:J200,"Отменена",'📋 Задачи'!M3:M200,$B$4) -> 0
A14: На согласовании | B14: =COUNTIFS('📋 Задачи'!J3:J200,"На согласовании",'📋 Задачи'!M3:M200,$B$4) -> 0
A15: Перенесено | B15: =COUNTIFS('📋 Задачи'!J3:J200,"Перенесена",'📋 Задачи'!M3:M200,$B$4) -> 0
A17: 📋 2. Разбивка по статусам (факт-квартал)
A18: Статус | B18: Кол-во | C18: % от всех
A19: Выполнена | B19: =COUNTIFS('📋 Задачи'!J3:J200,"Выполнена",'📋 Задачи'!N3:N200,$B$4) -> 1 | C19: =IFERROR(B19/SUM($B$19:$B$25),0) -> 1
A20: В работе | B20: =COUNTIFS('📋 Задачи'!J3:J200,"В работе",'📋 Задачи'!N3:N200,$B$4) -> 0 | C20: =IFERROR(B20/SUM($B$19:$B$25),0) -> 0
A21: В ожидании | B21: =COUNTIFS('📋 Задачи'!J3:J200,"В ожидании",'📋 Задачи'!N3:N200,$B$4) -> 0 | C21: =IFERROR(B21/SUM($B$19:$B$25),0) -> 0
A22: В бэклоге | B22: =COUNTIFS('📋 Задачи'!J3:J200,"В бэклоге",'📋 Задачи'!N3:N200,$B$4) -> 0 | C22: =IFERROR(B22/SUM($B$19:$B$25),0) -> 0
A23: Отменена | B23: =COUNTIFS('📋 Задачи'!J3:J200,"Отменена",'📋 Задачи'!N3:N200,$B$4) -> 0 | C23: =IFERROR(B23/SUM($B$19:$B$25),0) -> 0
A24: На согласовании | B24: =COUNTIFS('📋 Задачи'!J3:J200,"На согласовании",'📋 Задачи'!N3:N200,$B$4) -> 0 | C24: =IFERROR(B24/SUM($B$19:$B$25),0) -> 0
A25: Перенесена | B25: =COUNTIFS('📋 Задачи'!J3:J200,"Перенесена",'📋 Задачи'!N3:N200,$B$4) -> 0 | C25: =IFERROR(B25/SUM($B$19:$B$25),0) -> 0
A27: 🎯 3. Выполненные задачи по приоритету
A28: Приоритет | B28: Выполнено | C28: % от выполн.
A29: Высокий | B29: =COUNTIFS('📋 Задачи'!J3:J200,"Выполнена",'📋 Задачи'!K3:K200,"Высокий",'📋 Задачи'!N3:N200,$B$4) -> 1 | C29: =IFERROR(B29/B8,0) -> 1
A30: Средний | B30: =COUNTIFS('📋 Задачи'!J3:J200,"Выполнена",'📋 Задачи'!K3:K200,"Средний",'📋 Задачи'!N3:N200,$B$4) -> 0 | C30: =IFERROR(B30/B8,0) -> 0
A31: Низкий | B31: =COUNTIFS('📋 Задачи'!J3:J200,"Выполнена",'📋 Задачи'!K3:K200,"Низкий",'📋 Задачи'!N3:N200,$B$4) -> 0 | C31: =IFERROR(B31/B8,0) -> 0
A33: 📅 4. Годовая сводка по всем кварталам (2025)
A34: Квартал | B34: Поступило | C34: Выполнено | D34: В работе | E34: Отменено | F34: % выполнения
A35: Q1 2025 | B35: =COUNTIF('📋 Задачи'!M3:M200,"Q1 2025") -> 0 | C35: =COUNTIFS('📋 Задачи'!J3:J200,"Выполнена",'📋 Задачи'!N3:N200,"Q1 2025") -> 0 | D35: =COUNTIFS('📋 Задачи'!J3:J200,"В работе",'📋 Задачи'!M3:M200,"Q1 2025") -> 0 | E35: =COUNTIFS('📋 Задачи'!J3:J200,"Отменена",'📋 Задачи'!M3:M200,"Q1 2025") -> 0 | F35: =IFERROR(C35/B35,0) -> 0
A36: Q2 2025 | B36: =COUNTIF('📋 Задачи'!M3:M200,"Q2 2025") -> 1 | C36: =COUNTIFS('📋 Задачи'!J3:J200,"Выполнена",'📋 Задачи'!N3:N200,"Q2 2025") -> 1 | D36: =COUNTIFS('📋 Задачи'!J3:J200,"В работе",'📋 Задачи'!M3:M200,"Q2 2025") -> 0 | E36: =COUNTIFS('📋 Задачи'!J3:J200,"Отменена",'📋 Задачи'!M3:M200,"Q2 2025") -> 0 | F36: =IFERROR(C36/B36,0) -> 1
A37: Q3 2025 | B37: =COUNTIF('📋 Задачи'!M3:M200,"Q3 2025") -> 0 | C37: =COUNTIFS('📋 Задачи'!J3:J200,"Выполнена",'📋 Задачи'!N3:N200,"Q3 2025") -> 0 | D37: =COUNTIFS('📋 Задачи'!J3:J200,"В работе",'📋 Задачи'!M3:M200,"Q3 2025") -> 0 | E37: =COUNTIFS('📋 Задачи'!J3:J200,"Отменена",'📋 Задачи'!M3:M200,"Q3 2025") -> 0 | F37: =IFERROR(C37/B37,0) -> 0
A38: Q4 2025 | B38: =COUNTIF('📋 Задачи'!M3:M200,"Q4 2025") -> 0 | C38: =COUNTIFS('📋 Задачи'!J3:J200,"Выполнена",'📋 Задачи'!N3:N200,"Q4 2025") -> 0 | D38: =COUNTIFS('📋 Задачи'!J3:J200,"В работе",'📋 Задачи'!M3:M200,"Q4 2025") -> 0 | E38: =COUNTIFS('📋 Задачи'!J3:J200,"Отменена",'📋 Задачи'!M3:M200,"Q4 2025") -> 0 | F38: =IFERROR(C38/B38,0) -> 0
A39: ИТОГО | B39: =SUM(B35:B38) -> 1 | C39: =SUM(C35:C38) -> 1 | D39: =SUM(D35:D38) -> 0 | E39: =SUM(E35:E38) -> 0 | F39: =IFERROR(C39/B39,0) -> 1
A41: 🔧 5. Топ типов задач за квартал
A42: Тип задачи | B42: Кол-во | C42: Выполнено
A43: Анализ звонка | B43: =COUNTIFS('📋 Задачи'!R3:R200,"Анализ звонка",'📋 Задачи'!M3:M200,$B$4) -> 1 | C43: =COUNTIFS('📋 Задачи'!R3:R200,"Анализ звонка",'📋 Задачи'!J3:J200,"Выполнена",'📋 Задачи'!N3:N200,$B$4) -> 1
A44: Отчёт | B44: =COUNTIFS('📋 Задачи'!R3:R200,"Отчёт",'📋 Задачи'!M3:M200,$B$4) -> 0 | C44: =COUNTIFS('📋 Задачи'!R3:R200,"Отчёт",'📋 Задачи'!J3:J200,"Выполнена",'📋 Задачи'!N3:N200,$B$4) -> 0
A45: Техническая поддержка | B45: =COUNTIFS('📋 Задачи'!R3:R200,"Техническая поддержка",'📋 Задачи'!M3:M200,$B$4) -> 0 | C45: =COUNTIFS('📋 Задачи'!R3:R200,"Техническая поддержка",'📋 Задачи'!J3:J200,"Выполнена",'📋 Задачи'!N3:N200,$B$4) -> 0
A46: Настройка | B46: =COUNTIFS('📋 Задачи'!R3:R200,"Настройка",'📋 Задачи'!M3:M200,$B$4) -> 0 | C46: =COUNTIFS('📋 Задачи'!R3:R200,"Настройка",'📋 Задачи'!J3:J200,"Выполнена",'📋 Задачи'!N3:N200,$B$4) -> 0
...

Sheet 📚 Справочник
A1: 📚 СПРАВОЧНИК ЗНАЧЕНИЙ
A2: Статус задачи | B2: Приоритет | C2: Тип задачи | D2: Отдел / Управление
A3: Выполнена | B3: Высокий | C3: Анализ звонка | D3: Отдел кадров
A4: В работе | B4: Средний | C4: Отчёт | D4: Бухгалтерия
A5: В ожидании | B5: Низкий | C5: Техническая поддержка | D5: ИТ-отдел
A6: В бэклоге | C6: Настройка | D6: Юридический отдел
A7: Отменена | C7: Консультация | D7: Отдел продаж
A8: На согласовании | C8: Прочее | D8: Служба безопасности
A9: Перенесена | D9: Прочее
